Workbook

Sheet GK Main Data
A1: id | B1: post_type | C1: langu | D1: title | E1: category | F1: Category Decode | G1: subcategory | H1: SubCategory Decode | I1: section | J1: Section Decode | K1: image | L1: image_link | M1: documnet_link | N1: description | O1: created | P1: updated
A2: 73 | B2: GK | C2: English | D2: Abinash Bhattacharjee: Ghadar Patriot and Cellular Jail Freedom Fighter | E2: 1 | F2: =vlookup(E2,Category_ID!A:B,2,0) -> Indian History | G2: 3 | H2: =vlookup(G2,Sub_Category_ID!A:C,3,0) -> Modern History | I2: 39 | J2: =vlookup(I2,Section!A:D,4,0) -> Freedom Fighters and Their Contributions | K2: ddb7283023cc791ce80cb0e8ccc10815.jpg | M2: 1757059501_Abinash Chandra Bhattacharjee.pdf | N2: Abinash Chandra Bhattacharjee was a revolutionary associated with India’s early armed struggle for independence. Closely linked to the Jugantar Party and the Ghadar Movement, he was arrested for seditious activities and sentenced to Kala Pani at the Cellular Jail. He symbolizes the sacrifices made by young revolutionaries during the colonial era who fought British oppression through radical means. | O2: 0000-00-00 00:00:00 | P2: 0000-00-00 00:00:00
A3: 74 | B3: GK | C3: English | D3: Ullaskar Dutta: Revolutionary Bomb Maker Deported to Cellular Jail, Kalapani | F3: =vlookup(E3,Category_ID!A:B,2,0) -> #N/A | H3: =vlookup(G3,Sub_Category_ID!A:C,3,0) -> #N/A | J3: =vlookup(I3,Section!A:D,4,0) -> #N/A | K3: fdc645dcc65a9a071d66c06708f64be5.jpg | M3: 1757063597_Ullaskar Dutta.pdf | N3: Ullaskar Dutta was a prominent revolutionary associated with the Anushilan Samiti. Arrested in 1908 in the Alipore Bomb Case, he was sentenced to life and deported to the Cellular Jail in the Andamans. His incarceration saw extreme torture, leading to a mental breakdown. He was later released in 1915 and became a vocal critic of British colonial repression.\r\n | O3: 0000-00-00 00:00:00 | P3: 0000-00-00 00:00:00
A4: 75 | B4: GK | C4: English | D4: Indu Bhushan Roy: Forgotten Revolutionary Martyr of Cellular Jail History | F4: =vlookup(E4,Category_ID!A:B,2,0) -> #N/A | H4: =vlookup(G4,Sub_Category_ID!A:C,3,0) -> #N/A | J4: =vlookup(I4,Section!A:D,4,0) -> #N/A | K4: 402d1aa53aaa434c4de03d63b46cedf4.jpg | M4: 1757064614_Indu Bhushan Roy.pdf | N4: Indu Bhushan Roy was a valiant Bengali revolutionary linked with the Anushilan Samiti. Arrested for his involvement in armed resistance, he was deported to the infamous Cellular Jail in the Andamans. Tortured severely, he died under suspicious circumstances—likely suicide or custodial killing—becoming one of the earliest martyrs of Kalapani, symbolizing the brutality faced by political prisoners.\r\n | O4: 0000-00-00 00:00:00 | P4: 0000-00-00 00:00:00
A5: 76 | B5: GK | C5: English | D5: Trailokyanath Chakraborty: Voice Against Colonial Rule and Injustice | F5: =vlookup(E5,Category_ID!A:B,2,0) -> #N/A | H5: =vlookup(G5,Sub_Category_ID!A:C,3,0) -> #N/A | J5: =vlookup(I5,Section!A:D,4,0) -> #N/A | K5: b64688ee3f448233b303345726f5233f.jpg | M5: 1757064936_Trailokyanath Chakraborty.pdf | N5: Trailokyanath Chakraborty was a prominent Bengali revolutionary and freedom fighter associated with the Anushilan Samiti. Arrested multiple times by the British, he was deported to the Cellular Jail in the Andamans. Even after release, he remained active in the nationalist struggle. His life symbolized relentless resistance, ideological clarity, and sacrifice in the fight for India\'s independence.\r\n | O5: 0000-00-00 00:00:00 | P5: 0000-00-00 00:00:00
A6: 77 | B6: GK | C6: English | D6: Vinayak Damodar (Veer) Savarkar: Hindutva theorist, revolutionary, writer, and Cellular Jail prisoner | F6: =vlookup(E6,Category_ID!A:B,2,0) -> #N/A | H6: =vlookup(G6,Sub_Category_ID!A:C,3,0) -> #N/A | J6: =vlookup(I6,Section!A:D,4,0) -> #N/A | K6: 55c34eeb912e92cd21fecfd2accaa871.jpeg | M6: 1757065529_Vinayak Damodar (Veer) Savarkar.pdf | N6: Vinayak Damodar Savarkar (1883–1966) was a revolutionary, poet, and political ideologue who pioneered the concept of Hindutva. He founded Abhinav Bharat Society and influenced the armed struggle for India’s independence. Imprisoned in the Andamans, later led Hindu Mahasabha. Though controversial, he inspired generations with his writings and fearless resistance to colonial rule. | O6: 0000-00-00 00:00:00 | P6: 0000-00-00 00:00:00
A7: 78 | B7: GK | C7: English | D7: Bhai Parmanand: Arya Samaj missionary turned Ghadar revolutionary and Hindu Mahasabha leader | F7: =vlookup(E7,Category_ID!A:B,2,0) -> #N/A | H7: =vlookup(G7,Sub_Category_ID!A:C,3,0) -> #N/A | J7: =vlookup(I7,Section!A:D,4,0) -> #N/A | K7: d807de3df93081d81a481a904ace16ba.jpg | M7: 1757066018_Bhai Parmanand.pdf | N7: Bhai Parmanand (4 November 1876 – 8 December 1947) was a Mohyal Brahmin Arya Samajist from Punjab who travelled abroad as a missionary and connected with Lala Hardayal. A founding member of the Ghadar Party, he co-led the 1915 Lahore Conspiracy. Sentenced to death, later commuted to life, spent years in Andamans, launched a prolonged hunger strike, and later led Hindu Mahasabha.\r\n | O7: 0000-00-00 00:00:00 | P7: 0000-00-00 00:00:00
A8: 79 | B8: GK | C8: English | D8: Shambhu Nath Azad: Chambal-born revolutionary, hunger striker, daring bank raid leader | F8: =vlookup(E8,Category_ID!A:B,2,0) -> #N/A | H8: =vlookup(G8,Sub_Category_ID!A:C,3,0) -> #N/A | J8: =vlookup(I8,Section!A:D,4,0) -> #N/A | K8: 8f15513885e66033d803ad5e48eb4bd2.jpg | M8: 1757066603_Shambhu Nath Azad.pdf | N8: Shambhu Nath Azad, born in Agra (Kachhaura Ghat, Chambal region), joined Naujawan Bharat Sabha and Anushilan Samiti in his teens. Trained in guerrilla tactics, he formed a clandestine group (“Dasta”) in 1932 after release from jail. He orchestrated the daring Udhagamandalam (Ooty) bank robbery in April 1933 and endured long jail terms in Cellular Jail, including hunger strikes.\r\n | O8: 0000-00-00 00:00:00 | P8: 0000-00-00 00:00:00
A9: 80 | B9: GK | C9: English | D9: Upendra Nath Banerjee: Revolutionary Transported to Andamans for Sedition | E9: 1 | F9: =vlookup(E9,Category_ID!A:B,2,0) -> Indian History | G9: 3 | H9: =vlookup(G9,Sub_Category_ID!A:C,3,0) -> Modern History | I9: 39 | J9: =vlookup(I9,Section!A:D,4,0) -> Freedom Fighters and Their Contributions | K9: 2f45d6f666f0ab2b713f5e6b717cc8ca.jpg | M9: 1757067929_Upendra Nath Banerjee.pdf | N9: Upendra Nath Banerjee was a courageous revolutionary associated with the Anushilan Samiti. Arrested for his role in anti-British conspiracies, he was sentenced to Kala Pani—transportation for life to the Cellular Jail in the Andaman Islands. He represents a generation of patriots who dared to defy British colonialism through radical activism and underground movements.\r\n | O9: 0000-00-00 00:00:00 | P9: 0000-00-00 00:00:00
A10: 81 | B10: GK | C10: English | D10: Barindra Ghosh: Revolutionary Journalist and Alipore Bomb Case Accused | E10: 1 | F10: =vlookup(E10,Category_ID!A:B,2,0) -> Indian History | G10: 3 | H10: =vlookup(G10,Sub_Category_ID!A:C,3,0) -> Modern History | I10: 39 | J10: =vlookup(I10,Section!A:D,4,0) -> Freedom Fighters and Their Contributions | K10: 422135244a3242ff423aec17db4b8151.jpg | M10: 1757068265_Barindra Kumar Ghosh.pdf | N10: Barindra Kumar Ghosh was a key figure in India’s revolutionary nationalist movement and the younger brother of philosopher Sri Aurobindo. He founded the revolutionary journal Jugantar and was implicated in the Alipore Bomb Case. Initially sentenced to death, his punishment was commuted to life imprisonment in the Andaman’s Cellular Jail, marking his place in history among the notable Kala Pani convicts.\r\n | O10: 0000-00-00 00:00:00 | P10: 0000-00-00 00:00:00
A11: 82 | B11: GK | C11: English | D11: Mohit Moitra: Martyr of Cellular Jail’s Historic 1933 Hunger Strike | E11: 1 | F11: =vlookup(E11,Category_ID!A:B,2,0) -> Indian History | G11: 3 | H11: =vlookup(G11,Sub_Category_ID!A:C,3,0) -> Modern History | I11: 39 | J11: =vlookup(I11,Section!A:D,4,0) -> Freedom Fighters and Their Contributions | K11: 70dfddee4571ae1fcdaf5f556579d4b4.jpg | M11: 1757068791_Mohit Moitra.pdf | N11: Mohit Moitra was a Bengali revolutionary and a member of the Jugantar group. Arrested for his anti-British activities, he was deported to the Cellular Jail. In 1933, he joined a hunger strike to protest the inhumane treatment of political prisoners. He died after being forcibly fed by jail authorities, becoming one of the three martyrs of that strike.\r\n | O11: 0000-00-00 00:00:00 | P11: 0000-00-00 00:00:00
A12: 83 | B12: GK | C12: English | D12: Mohan Kishore Namadas: Revolutionary Martyr of Cellular Jail Hunger Strike | E12: 1 | F12: =vlookup(E12,Category_ID!A:B,2,0) -> Indian History | G12: 3 | H12: =vlookup(G12,Sub_Category_ID!A:C,3,0) -> Modern History | I12: 39 | J12: =vlookup(I12,Section!A:D,4,0) -> Freedom Fighters and Their Contributions | K12: ae2dfbb25e06bafb627e0a3fed83e921.jpg | M12: 1757069671_Mohan Kishore Namadas.pdf | N12: Mohan Kishore Namadas, a Bengali revolutionary, was a key member of the Anushilan Samiti. Arrested for revolutionary activities, he was sentenced to life imprisonment and deported to the Cellular Jail. In 1933, during a hunger strike for better treatment of political prisoners, he died due to brutal forced feeding. His martyrdom highlighted British cruelty in penal colonies.\r\n | O12: 0000-00-00 00:00:00 | P12: 0000-00-00 00:00:00
A13: 84 | B13: GK | C13: English | D13: Mahavir Singh: Martyr Who Defied British Rule in Cellular Jail | E13: 1 | F13: =vlookup(E13,Category_ID!A:B,2,0) -> Indian History | G13: 3 | H13: =vlookup(G13,Sub_Category_ID!A:C,3,0) -> Modern History | I13: 39 | J13: =vlookup(I13,Section!A:D,4,0) -> Freedom Fighters and Their Contributions | K13: 6d5a8fe51ebaf2164a78891b0e9d06cb.jpg | M13: 1757071092_Mahavir Singh.pdf | N13: Mahavir Singh, a courageous revolutionary from Uttar Pradesh, joined the Hindustan Socialist Republican Association (HSRA). He was imprisoned and sent to the Cellular Jail in the Andamans. While protesting against the brutal treatment of fellow prisoners, he undertook a hunger strike. He died during forced feeding, becoming one of the first martyrs of Cellular Jail.\r\n | O13: 0000-00-00 00:00:00 | P13: 0000-00-00 00:00:00
A14: 85 | B14: GK | C14: English | D14: Khudiram Bose: Young Revolutionary, Symbol of Courage and Sacrifice | E14: 1 | F14: =vlookup(E14,Category_ID!A:B,2,0) -> Indian History | G14: 3 | H14: =vlookup(G14,Sub_Category_ID!A:C,3,0) -> Modern History | I14: 39 | J14: =vlookup(I14,Section!A:D,4,0) -> Freedom Fighters and Their Contributions | K14: 7344218a1ddddb2d945fd211ec5f1ae3.jpg | M14: 1757071333_Khudiram Bosh.pdf | N14: Khudiram Bose was one of India’s youngest freedom fighters, martyred at just 18. Born in Midnapore in 1889, he joined the revolutionary Anushilan Samiti. In the Muzaffarpur Conspiracy Case, he attempted to assassinate a British judge but mistakenly killed two women. Captured and hanged in 1908, he remains a symbol of courage, with his legacy honored across India.\r\n | O14: 0000-00-00 00:00:00 | P14: 0000-00-00 00:00:00
A15: 86 | B15: GK | C15: English | D15: Bhagat Singh: Revolutionary Icon Who Challenged British Rule with Courage | E15: 1 | F15: =vlookup(E15,Category_ID!A:B,2,0) -> Indian History | G15: 3 | H15: =vlookup(G15,Sub_Category_ID!A:C,3,0) -> Modern History | I15: 39 | J15: =vlookup(I15,Section!A:D,4,0) -> Freedom Fighters and Their Contributions | K15: 788ef6588d28d28962e494f858e953ae.jpg | M15: 1757072129_Bhagat Singh.pdf | N15: Bhagat Singh was a socialist revolutionary who opposed British colonialism through radical means. Influenced by Marxism and nationalism, he participated in significant acts like the Assembly bombing and Saunders\' assassination. Hanged at 23, he became a martyr. His legacy inspires youth, symbolizing bravery, ideology-driven action, and ultimate sacrifice for India’s freedom.\r\n | O15: 0000-00-00 00:00:00 | P15: 0000-00-00 00:00:00
A16: 87 | B16: GK | C16: English | D16: Shivaram Rajguru: Brave Revolutionary and Martyr of India’s Freedom Struggle | E16: 1 | F16: =vlookup(E16,Category_ID!A:B,2,0) -> Indian History | G16: 3 | H16: =vlookup(G16,Sub_Category_ID!A:C,3,0) -> Modern History | I16: 39 | J16: =vlookup(I16,Section!A:D,4,0) -> Freedom Fighters and Their Contributions | K16: d5b68ffd2c68b4efafabe099a7172cf2.jpg | M16: 1757072632_Shivaram Rajguru.pdf | N16: Shivaram Rajguru was a fearless revolutionary from Maharashtra who fought against British rule. As a member of HSRA, he participated in the assassination of British officer John Saunders alongside Bhagat Singh and Sukhdev. A firm believer in armed resistance, Rajguru was hanged on 23 March 1931. He is remembered as a symbol of youthful sacrifice and patriotism.\r\n | O16: 0000-00-00 00:00:00 | P16: 0000-00-00 00:00:00
A17: 88 | B17: GK | C17: English | D17: Sukhdev Thapar: Committed Revolutionary and Martyr of India’s Freedom Struggle | E17: 1 | F17: =vlookup(E17,Category_ID!A:B,2,0) -> Indian History | G17: 3 | H17: =vlookup(G17,Sub_Category_ID!A:C,3,0) -> Modern History | I17: 39 | J17: =vlookup(I17,Section!A:D,4,0) -> Freedom Fighters and Their Contributions | K17: 0433c45fdd396b4371b821c486b16e6d.jpg | M17: 1757072988_Sukhdev Thapar.pdf | N17: Sukhdev Thapar was a dedicated revolutionary from Punjab who played a key role in India’s freedom struggle. As a senior member of HSRA, he helped organize revolutionary cells and participated in the Saunders assassination. Known for his discipline and leadership, he was executed with Bhagat Singh and Rajguru on 23 March 1931. His martyrdom remains an inspiration.\r\n | O17: 0000-00-00 00:00:00 | P17: 0000-00-00 00:00:00
A18: 89 | B18: GK | C18: English | D18: Ram Prasad Bismil: Poet Revolutionary Behind Kakori Conspiracy Against British Rule | E18: 1 | F18: =vlookup(E18,Category_ID!A:B,2,0) -> Indian History | G18: 3 | H18: =vlookup(G18,Sub_Category_ID!A:C,3,0) -> Modern History | I18: 39 | J18: =vlookup(I18,Section!A:D,4,0) -> Freedom Fighters and Their Contributions | K18: f1a81f2838d15bf27ab7fcfaffad95d2.jpg | M18: 1757073299_Ram Prasad Bismil.pdf | N18: Ram Prasad Bismil was a prominent revolutionary, poet, and freedom fighter who fought British colonialism through armed struggle. He co-founded the Hindustan Republican Association (HRA) and led the famous Kakori Train Robbery of 1925. A powerful orator and nationalist poet, Bismil was executed in 1927, leaving behind a legacy of patriotism and poetic resistance.\r\n | O18: 0000-00-00 00:00:00 | P18: 0000-00-00 00:00:00
A19: 90 | B19: GK | C19: English | D19: Ashfaqulla Khan: Martyr Who Fought British Rule With Brotherhood | E19: 1 | F19: =vlookup(E19,Category_ID!A:B,2,0) -> Indian History | G19: 3 | H19: =vlookup(G19,Sub_Category_ID!A:C,3,0) -> Modern History | I19: 39 | J19: =vlookup(I19,Section!A:D,4,0) -> Freedom Fighters and Their Contributions | K19: a29c7b82effec14da37d2e93593aaf8e.jpg | M19: 1757073643_Ashfaqulla Khan.pdf | N19: Ashfaqulla Khan was a freedom fighter and poet who fought British colonialism through revolutionary means. As a key member of the Hindustan Republican Association, he took part in the Kakori Train Robbery. Committed to Hindu-Muslim unity and patriotic ideals, he was executed in 1927. His martyrdom stands as a symbol of secular nationalism and youthful sacrifice.\r\n | O19: 0000-00-00 00:00:00 | P19: 0000-00-00 00:00:00
A20: 91 | B20: GK | C20: English | D20: Thakur Roshan Singh: Forgotten Martyr of the Kakori Conspiracy Case | E20: 1 | F20: =vlookup(E20,Category_ID!A:B,2,0) -> Indian History | G20: 3 | H20: =vlookup(G20,Sub_Category_ID!A:C,3,0) -> Modern History | I20: 39 | J20: =vlookup(I20,Section!A:D,4,0) -> Freedom Fighters and Their Contributions | K20: b2ab35ab250a47fd14a94d9ef3981376.jpg | M20: 1757073855_Thakur Roshan Singh.pdf | N20: Thakur Roshan Singh was a revolutionary associated with the Hindustan Republican Association. Though not directly involved in the Kakori train robbery, he was arrested for earlier revolutionary actions and executed for conspiracy. He was hanged on 19 December 1927, alongside Ashfaqulla Khan and Ram Prasad Bismil, marking him as one of the silent martyrs of India’s freedom movement.\r\n | O20: 0000-00-00 00:00:00 | P20: 0000-00-00 00:00:00
... A23: 94 | B23: GK | C23: English | D23: Mangal Pandey Ignited 1857 Revolt, Defied British Colonial Oppression Boldly | E23: 1 | F23: =vlookup(E23,Category_ID!A:B,2,0) -> Indian History | G23: 3 | H23: =vlookup(G23,Sub_Category_ID!A:C,3,0) -> Modern History | I23: 39 | J23: =vlookup(I23,Section!A:D,4,0) -> Freedom Fighters and Their Contributions | K23: 26343e02ac546ffd4d9eccdb13300c8b.jpg | M23: 1757075121_Mangal Pandey.pdf | N23: Mangal Pandey, a sepoy in the 34th Bengal Native Infantry, ignited India’s First War of Independence in 1857 by revolting against the use of greased rifle cartridges that insulted Hindu and Muslim religious sentiments. His act of rebellion at Barrackpore led to his execution but became the symbolic starting point of India\'s armed struggle against British colonial rule.\r\n | O23: 0000-00-00 00:00:00 | P23: 0000-00-00 00:00:00
A24: 95 | B24: GK | C24: English | D24: sdcwnsdcn | F24: =vlookup(E24,Category_ID!A:B,2,0) -> #N/A | H24: =vlookup(G24,Sub_Category_ID!A:C,3,0) -> #N/A | I24: 1 | J24: =vlookup(I24,Section!A:D,4,0) -> #N/A | K24: 16a1bb5ce98eeba49f8152c14999fd79.png | L24: https://example.com/images/history.jpg | M24: 1757171713_Advance_Topic.pdf | N24: wsdvesvc | O24: 0000-00-00 00:00:00 | P24: 0000-00-00 00:00:00
A25: 96 | B25: GK | C25: English | D25: Udham Singh Avenged Jallianwala Bagh Massacre, Martyred in London | E25: 1 | F25: =vlookup(E25,Category_ID!A:B,2,0) -> Indian History | G25: 3 | H25: =vlookup(G25,Sub_Category_ID!A:C,3,0) -> Modern History | I25: 39 | J25: =vlookup(I25,Section!A:D,4,0) -> Freedom Fighters and Their Contributions | K25: 6e91ca4aeeec6f9a885bfe8885e514b6.jpg | M25: 1757323013_Udham Singh.pdf | N25: Udham Singh, a revolutionary from Punjab, assassinated General Michael O\'Dwyer in 1940 to avenge the 1919 Jallianwala Bagh massacre. A member of the Ghadar Party and later influenced by socialism, Singh waited over two decades for justice. Captured and tried in Britain, he was hanged in London. His sacrifice is remembered as a symbol of anti-colonial vengeance and resistance.\r\n | O25: 0000-00-00 00:00:00 | P25: 0000-00-00 00:00:00
A26: 97 | B26: GK | C26: English | D26: Teen Revolutionary Anant Kanhere Hanged for Killing British Collector Jackson | E26: 1 | F26: =vlookup(E26,Category_ID!A:B,2,0) -> Indian History | G26: 3 | H26: =vlookup(G26,Sub_Category_ID!A:C,3,0) -> Modern History | I26: 39 | J26: =vlookup(I26,Section!A:D,4,0) -> Freedom Fighters and Their Contributions | K26: 532922707e0ef6135c1f61eb069b026c.jpg | L26: https://example.com/images/history.jpg | M26: 1757323586_Anant Laxman Kanher.pdf | N26: Anant Laxman Kanher, a young revolutionary from Maharashtra, assassinated British Collector A.M.T. Jackson in 1909 to protest colonial oppression. Influenced by nationalist ideals, he carried out the act at a public event in Nashik. Arrested on the spot, he was tried and hanged at age 18 in 1910. His execution remains a symbol of youthful sacrifice in India’s freedom movement.\r\n | O26: 0000-00-00 00:00:00 | P26: 0000-00-00 00:00:00
A27: 98 | B27: GK | C27: English | D27: Teen Freedom Fighter Hemu Kalani Hanged by British at Nineteen | E27: 1 | F27: =vlookup(E27,Category_ID!A:B,2,0) -> Indian History | G27: 3 | H27: =vlookup(G27,Sub_Category_ID!A:C,3,0) -> Modern History | I27: 39 | J27: =vlookup(I27,Section!A:D,4,0) -> Freedom Fighters and Their Contributions | K27: e2a1e35472cb0c7621545c2533bd960f.jpg | M27: 1757323736_Hemu Kalani.pdf | N27: Hemu Kalani was a teenage revolutionary from Sindh who led anti-British protests during the Quit India Movement. He attempted to derail a British military train carrying troops and arms. Caught and tortured, Hemu refused to betray his comrades. He was hanged on January 21, 1943, becoming one of the youngest martyrs of India’s struggle for independence.\r\n | O27: 0000-00-00 00:00:00 | P27: 0000-00-00 00:00:00
A28: 99 | B28: GK | C28: English | D28: Satyendranath Bosu Hanged For Role In Chittagong Armoury Raid | E28: 1 | F28: =vlookup(E28,Category_ID!A:B,2,0) -> Indian History | G28: 3 | H28: =vlookup(G28,Sub_Category_ID!A:C,3,0) -> Modern History | I28: 39 | J28: =vlookup(I28,Section!A:D,4,0) -> Freedom Fighters and Their Contributions | K28: 503e30b9542bd1b84eef19f9f5606835.jpg | M28: 1757324132_Satyendranath Bosu .pdf | N28: Satyendranath Bosu was a Bengali revolutionary associated with the Chittagong Armoury Raid of 1930 led by Surya Sen. Deeply inspired by nationalist ideas, he played a key role in the armed insurrection against British rule. Captured after the raid, he was sentenced to death and hanged in July 1934, becoming one of the unsung heroes of India’s independence movement.\r\n | O28: 0000-00-00 00:00:00 | P28: 0000-00-00 00:00:00
A29: 100 | B29: GK | C29: English | D29: Ramkrishna Biswas Hanged for Attempted Assassination of British Officer | E29: 1 | F29: =vlookup(E29,Category_ID!A:B,2,0) -> Indian History | G29: 3 | H29: =vlookup(G29,Sub_Category_ID!A:C,3,0) -> Modern History | I29: 39 | J29: =vlookup(I29,Section!A:D,4,0) -> Freedom Fighters and Their Contributions | K29: c43344f70928ccd15603430f1f37fa86.jpg | M29: 1757324701_Ramkrishna Biswas .pdf | N29: Ramkrishna Biswas was a revolutionary from Bengal associated with the Jugantar group. In 1930, he attempted to assassinate a British magistrate as an act of anti-colonial resistance but mistakenly killed another officer. He was arrested, tried, and hanged in 1931. His execution inspired numerous revolutionaries, including Subhas Chandra Bose, and remains a symbol of youthful sacrifice.\r\n | O29: 0000-00-00 00:00:00 | P29: 0000-00-00 00:00:00
A30: 101 | B30: GK | C30: English | D30: Ghulam Husain Martyred For Role In Chittagong Armoury Raid, 1934 | E30: 1 | F30: =vlookup(E30,Category_ID!A:B,2,0) -> Indian History | G30: 3 | H30: =vlookup(G30,Sub_Category_ID!A:C,3,0) -> Modern History | I30: 39 | J30: =vlookup(I30,Section!A:D,4,0) -> Freedom Fighters and Their Contributions | K30: 94a696c0c056c066d6b6b29f03f5724c.jpg | M30: 1757325085_Ghulam Husain .pdf | N30: Ghulam Husain, a brave revolutionary from Bengal, participated in the Chittagong Armoury Raid of 1930, orchestrated by Surya Sen. His mission was to liberate India through armed rebellion. Arrested during the British crackdown, he was sentenced to death and hanged in July 1934. Though less known, he remains an important figure in India\'s armed freedom struggle.\r\n | O30: 0000-00-00 00:00:00 | P30: 0000-00-00 00:00:00
A31: 102 | B31: GK | C31: English | D31: Basanta Kumar Biswas: Young Revolutionary Hanged for Delhi Bomb Attack | E31: 1 | F31: =vlookup(E31,Category_ID!A:B,2,0) -> Indian History | G31: 3 | H31: =vlookup(G31,Sub_Category_ID!A:C,3,0) -> Modern History | I31: 39 | J31: =vlookup(I31,Section!A:D,4,0) -> Freedom Fighters and Their Contributions | K31: f28eb9a77995657b79378d1e2d2fcdaa.jpg | M31: 1757325978_Basanta Kumar Biswas.pdf | N31: Basanta Kumar Biswas, a young Bengali revolutionary, played a key role in the 1912 Delhi Conspiracy. At just 18, he was involved in an assassination attempt on Viceroy Lord Hardinge during a state procession. Arrested and tried under the British regime, he was hanged on 11 May 1915. His sacrifice remains a powerful symbol of youthful patriotism.\r\n | O31: 0000-00-00 00:00:00 | P31: 0000-00-00 00:00:00
A32: 103 | B32: GK | C32: English | D32: Bhai Balmukund: Delhi Conspiracy Martyr Executed in British India | E32: 1 | F32: =vlookup(E32,Category_ID!A:B,2,0) -> Indian History | G32: 3 | H32: =vlookup(G32,Sub_Category_ID!A:C,3,0) -> Modern History | I32: 39 | J32: =vlookup(I32,Section!A:D,4,0) -> Freedom Fighters and Their Contributions | K32: 12a2d9019baf49f29d2ea5285ecd6b93.jpg | M32: 1757326643_Bhai Balmukund.pdf | N32: Bhai Balmukund was a revolutionary deeply involved in the 1912 Delhi Conspiracy, which targeted Viceroy Lord Hardinge. A cousin of revolutionary Bhai Parmanand, Balmukund was arrested in 1914, tried under charges of conspiracy and sedition, and hanged at the Lahore Central Jail in May 1915. He remains remembered as a brave nationalist who sacrificed his life at just 26.\r\n | O32: 0000-00-00 00:00:00 | P32: 0000-00-00 00:00:00
A33: 104 | B33: GK | C33: English | D33: Tatya Tope Led Fierce Guerrilla Campaigns During 1857 Revolt Heroically | E33: 1 | F33: =vlookup(E33,Category_ID!A:B,2,0) -> Indian History | G33: 3 | H33: =vlookup(G33,Sub_Category_ID!A:C,3,0) -> Modern History | I33: 39 | J33: =vlookup(I33,Section!A:D,4,0) -> Freedom Fighters and Their Contributions | K33: fc00efc148feda71e54ddfb9e3aacd6d.jpg | M33: 1757320745_Tatya Tope.pdf | N33: Tatya Tope, a key leader in the 1857 Revolt, was a trusted general of Nana Sahib. Known for his strategic brilliance and guerrilla warfare, he led forces in Kanpur, Gwalior, and central India. Even after losing territory, he continued resistance until captured and executed in 1859. Tatya remains one of India’s earliest revolutionary icons for his unmatched military defiance. | O33: 0000-00-00 00:00:00 | P33: 0000-00-00 00:00:00
A34: 105 | B34: GK | C34: English | D34: Vanchinathan Assassinated British Collector, Sparked Early Nationalist Resistance | E34: 1 | F34: =vlookup(E34,Category_ID!A:B,2,0) -> Indian History | G34: 3 | H34: =vlookup(G34,Sub_Category_ID!A:C,3,0) -> Modern History | I34: 39 | J34: =vlookup(I34,Section!A:D,4,0) -> Freedom Fighters and Their Contributions | K34: f4636d46aa34840f203aef4ab59d4c1c.jpg | M34: 1757321161_Vanchinathan Iyer.pdf | N34: Vanchinathan was a Tamil revolutionary who assassinated British Collector Robert Ashe in 1911 at Maniyachi railway station. Motivated by the Swadeshi movement and colonial atrocities, he viewed Ashe as an oppressor. After the act, Vanchinathan died by suicide to avoid capture. Though controversial, he remains a symbol of early militant resistance in India’s freedom struggle, especially in South India.\r\n | O34: 0000-00-00 00:00:00 | P34: 0000-00-00 00:00:00
A35: 106 | B35: GK | C35: English | D35: Dinesh Gupta Fought Colonial Rule, Embraced Martyrdom With Courage | E35: 1 | F35: =vlookup(E35,Category_ID!A:B,2,0) -> Indian History | G35: 3 | H35: =vlookup(G35,Sub_Category_ID!A:C,3,0) -> Modern History | I35: 39 | J35: =vlookup(I35,Section!A:D,4,0) -> Freedom Fighters and Their Contributions | K35: 55a54b3b9621cb2f74952b38edc437b2.jpg | M35: 1757321583_Dinesh Gupta.pdf | N35: Dinesh Gupta, a young Bengali revolutionary, was a key figure in India’s anti-colonial movement. In 1931, he and his comrades attacked the Writers’ Building in Kolkata to assassinate British officials. Though the mission partly failed, Gupta was captured and executed at just 19. His bravery and sacrifice remain etched in the history of Bengal’s revolutionary struggle against British rule.\r\n | O35: 0000-00-00 00:00:00 | P35: 0000-00-00 00:00:00
A36: 107 | B36: GK | C36: English | D36: Kartar Singh Sarabha Inspired Ghadar Movement, Martyred at Age Nineteen | E36: 1 | F36: =vlookup(E36,Category_ID!A:B,2,0) -> Indian History | G36: 3 | H36: =vlookup(G36,Sub_Category_ID!A:C,3,0) -> Modern History | I36: 39 | J36: =vlookup(I36,Section!A:D,4,0) -> Freedom Fighters and Their Contributions | K36: 69082f39abe02ae66e8fde17be2231ab.jpg | M36: 1757322239_Kartar Singh Sarabha.pdf | N36: Kartar Singh Sarabha was a fiery revolutionary and one of the youngest martyrs of India’s freedom struggle. A leader of the Ghadar Movement, he sought to incite mutiny in the British Indian Army during World War I. Caught by the British, he was tried and hanged at the age of 19. His sacrifice deeply inspired revolutionaries like Bhagat Singh. | O36: 0000-00-00 00:00:00 | P36: 0000-00-00 00:00:00
A37: 108 | B37: GK | C37: English | D37: Pandit Kanshi Ram: Ghadar Revolutionary Martyred for India’s Freedom Struggle | E37: 1 | F37: =vlookup(E37,Category_ID!A:B,2,0) -> Indian History | G37: 3 | H37: =vlookup(G37,Sub_Category_ID!A:C,3,0) -> Modern History | I37: 39 | J37: =vlookup(I37,Section!A:D,4,0) -> Freedom Fighters and Their Contributions | K37: fa260a13552ab5757cc6cbf54d388f2d.jpg | M37: 1757327281_Pandit Kanshi Ram.pdf | N37: Pandit Kanshi Ram was a key leader in the Ghadar Movement, which aimed to incite armed revolt against British rule in India. A close associate of Lala Hardayal and Vishnu Ganesh Pingle, he was arrested for attempting mutiny in the British Indian Army. He was tried under the Lahore Conspiracy Case and hanged in Lahore on 27 March 1915.\r\n | O37: 0000-00-00 00:00:00 | P37: 0000-00-00 00:00:00
A38: 109 | B38: GK | C38: English | D38: Babarao Savarkar: Revolutionary Who Faced Kala Pani Punishment Bravely | E38: 1 | F38: =vlookup(E38,Category_ID!A:B,2,0) -> Indian History | G38: 3 | H38: =vlookup(G38,Sub_Category_ID!A:C,3,0) -> Modern History | I38: 39 | J38: =vlookup(I38,Section!A:D,4,0) -> Freedom Fighters and Their Contributions | K38: 9e21d0144e3631ba58175ea10afcc638.jpg | M38: 1757328080_Babarao Savarkar.pdf | N38: Babarao Savarkar, elder brother of Veer Savarkar, was a fearless revolutionary and co-founder of the Abhinav Bharat Society. Convicted for sedition, he was sentenced to Kala Pani at Cellular Jail, Andaman. Despite harsh conditions, he remained committed to India’s independence. A forgotten patriot, his life embodies the unsung sacrifices made in India’s freedom movement.\r\n | O38: 0000-00-00 00:00:00 | P38: 0000-00-00 00:00:00
... A60: 131 | B60: GK | C60: English | D60: India’s Parliament: Structure, Lawmaking, Committees, and Privileges Explained | E60: 5 | F60: =vlookup(E60,Category_ID!A:B,2,0) -> Polity and Governance | G60: 28 | H60: =vlookup(G60,Sub_Category_ID!A:C,3,0) -> Indian Constitution | I60: 59 | J60: =vlookup(I60,Section!A:D,4,0) -> Union Government | K60: 8f6babc8a0524edccbc1182659d650f6.jpg | M60: 1757412737_India’s Parliament_ Structure, Lawmaking, Committees, and Privileges Explained.pdf | N60: India’s Parliament, comprising the President, Lok Sabha, and Rajya Sabha, is central to governance. It frames laws through a structured legislative process, aided by specialized committees. Parliamentary privileges safeguard members’ independence but face criticism for misuse and ambiguity. Key judicial rulings and reforms aim to balance these privileges with transparency, accountability, and the democratic spirit.\r\n | O60: 0000-00-00 00:00:00 | P60: 0000-00-00 00:00:00
A61: 132 | B61: GK | C61: English | D61: Judiciary in India: Balancing Activism, Restraint, and Constitutional Mandates | E61: 5 | F61: =vlookup(E61,Category_ID!A:B,2,0) -> Polity and Governance | G61: 28 | H61: =vlookup(G61,Sub_Category_ID!A:C,3,0) -> Indian Constitution | I61: 59 | J61: =vlookup(I61,Section!A:D,4,0) -> Union Government | K61: be1cac4a648d4af9bb2741af4b4254e2.png | M61: 1757413505_Judiciary in India_ Balancing Activism, Restraint, and Constitutional Mandates.pdf | N61: The Indian judiciary plays a pivotal role in safeguarding constitutional rights through judicial review, activism, and restraint. While activism advances rights and fills legislative gaps, overreach risks undermining separation of powers. Landmark cases like Kesavananda Bharati, Maneka Gandhi, and Vishaka shaped public law, highlighting the judiciary’s role in democracy, yet emphasizing the need for principled limits.\r\n | O61: 0000-00-00 00:00:00 | P61: 45934.569
A62: 133 | B62: GK | C62: English | D62: Constitutional Role, Powers, and Challenges of India’s State Governors | E62: 5 | F62: =vlookup(E62,Category_ID!A:B,2,0) -> Polity and Governance | G62: 28 | H62: =vlookup(G62,Sub_Category_ID!A:C,3,0) -> Indian Constitution | I62: 60 | J62: =vlookup(I62,Section!A:D,4,0) -> State Government | K62: 8c9186b25f7ecea9603e9ce1c3223c58.jpg | M62: 1757413747_Constitutional Role, Powers, and Challenges of India’s State Governors.pdf | N62: The Governor, India’s constitutional head of state, bridges the Centre and State. Appointed by the President, the role carries executive, legislative, and judicial powers, balanced by constitutional conventions and judicial rulings. While intended as a neutral office, controversies over political bias, misuse of Article 356, and delayed bill assent persist, prompting calls for reforms and stricter accountability.\r\n | O62: 0000-00-00 00:00:00 | P62: 0000-00-00 00:00:00
A63: 134 | B63: GK | C63: English | D63: Chief Minister and Council: Pillars of India’s State Governance | E63: 5 | F63: =vlookup(E63,Category_ID!A:B,2,0) -> Polity and Governance | G63: 28 | H63: =vlookup(G63,Sub_Category_ID!A:C,3,0) -> Indian Constitution | I63: 60 | J63: =vlookup(I63,Section!A:D,4,0) -> State Government | K63: a681913d0730d53e33d06740e29c732c.png | M63: 1757415167_Chief Minister and Council_ Pillars of India’s State Governance.pdf | N63: The Chief Minister and Council of Ministers form the real executive at the state level, guiding policy, legislation, and administration within India’s federal framework. Appointed by the Governor, they operate under collective and individual responsibility to the Legislative Assembly. Bound by constitutional provisions, they ensure governance continuity, uphold democratic principles, and act as the state’s decision-making core.\r\n | O63: 0000-00-00 00:00:00 | P63: 0000-00-00 00:00:00
...

Sheet Category_ID
A1: id | B1: category_name | C1: status | D1: created_at
A2: 1 | B2: Indian History | C2: 1 | D2: 45905.642
A3: 2 | B3: Indian Geography | C3: 1 | D3: 45905.642
A4: 3 | B4: World Geography | C4: 1 | D4: 45905.642
A5: 4 | B5: Map Work | C5: 1 | D5: 45905.642
A6: 5 | B6: Polity and Governance | C6: 1 | D6: 45905.642
A7: 6 | B7: Indian Economy | C7: 1 | D7: 45905.642
A8: 7 | B8: General Science | C8: 1 | D8: 45905.642
A9: 8 | B9: Environment and Ecology | C9: 1 | D9: 45905.642
A10: 9 | B10: Indian Art and Culture | C10: 1 | D10: 45905.642
A11: 10 | B11: International Relations | C11: 1 | D11: 45905.642
A12: 11 | B12: Static GK | C12: 1 | D12: 45905.642
A13: 12 | B13: Science and Technology | C13: 1 | D13: 45905.642
... A17: 16 | B17: Verbal Ability | C17: 1 | D17: 45905.642

Sheet Sub_Category_ID
A1: id | B1: category_id | C1: sub_category_name | D1: status | E1: created_at
A2: 2 | B2: 1 | C2: Medieval History | D2: 1 | E2: 45905.707
A3: 3 | B3: 1 | C3: Modern History | D3: 1 | E3: 45906.52
A4: 21 | B4: 1 | C4: Ancient History | D4: 1 | E4: 45907.439
A5: 25 | B5: 2 | C5: Physical Geography | D5: 1 | E5: 45908.193
A6: 26 | B6: 2 | C6: Human Geography | D6: 1 | E6: 45908.193
A7: 27 | B7: 2 | C7: Economic Geography | D7: 1 | E7: 45908.193
A8: 28 | B8: 5 | C8: Indian Constitution | D8: 1 | E8: 45908.461
A9: 29 | B9: 5 | C9: Indian Political System | D9: 1 | E9: 45908.462
A10: 30 | B10: 5 | C10: Governance | D10: 1 | E10: 45908.463
A11: 31 | B11: 6 | C11: Basic Concepts | D11: 1 | E11: 45911.482
A12: 32 | B12: 6 | C12: Sectors of Economy | D12: 1 | E12: 45911.483
A13: 33 | B13: 6 | C13: Government Schemes & Reforms | D13: 1 | E13: 45911.483
... A30: 51 | B30: 16 | C30: Verbal Ability | D30: 1 | E30: 45975.269

Sheet Section
A1: Id | B1: category_id | C1: sub_category_id | D1: section_name | E1: section_tip | F1: status | G1: created_at
A2: 18 | B2: 1 | C2: 21 | D2: Indus Valley Civilization | F2: 1 | G2: 45907.452
A3: 19 | B3: 1 | C3: 21 | D3: Vedic Age | F3: 1 | G3: 45907.611
A4: 20 | B4: 1 | C4: 21 | D4: Mahajanapadas | F4: 1 | G4: 45907.612
A5: 21 | B5: 1 | C5: 21 | D5: Mauryan Empire | F5: 1 | G5: 45907.612
A6: 22 | B6: 1 | C6: 21 | D6: Post-Mauryan India (Sunga, Kushana, Gupta) | F6: 1 | G6: 45907.612
A7: 23 | B7: 1 | C7: 21 | D7: South Indian Dynasties (Sangam Age, Cholas, Cheras, Pandyas) | F7: 1 | G7: 45907.613
A8: 24 | B8: 1 | C8: 21 | D8: Religious Movements: Buddhism, Jainism | F8: 1 | G8: 45907.613
A9: 25 | B9: 1 | C9: 21 | D9: Art, Culture, and Architecture | F9: 1 | G9: 45907.613
A10: 26 | B10: 1 | C10: 2 | D10: Delhi Sultanate | F10: 1 | G10: 45907.627
A11: 27 | B11: 1 | C11: 2 | D11: Mughal Empire | F11: 1 | G11: 45907.627
A12: 28 | B12: 1 | C12: 2 | D12: Regional Kingdoms | F12: 1 | G12: 45907.627
A13: 29 | B13: 1 | C13: 2 | D13: Bhakti and Sufi Movements | F13: 1 | G13: 45907.628
... A103: 124 | B103: 11 | C103: 37 | D103: First Achievers | F103: 1 | G103: 45938.976
A104: 127 | B104: 13 | C104: 46 | D104: Percentage | E104: 1763094925_Screenshot2025-11-02at6.05.18P.jpeg | F104: 1 | G104: 45975.191
A105: 128 | B105: 13 | C105: 46 | D105: Profit & Loss | E105: 1763099489_24895956_b9cb653b-a9c9-477b-bb6f-627750effaad_lg.png | F105: 1 | G105: 45975.232
A106: 129 | B106: 13 | C106: 46 | D106: Simple & Compound Interest | E106: 1763185249_Screenshot 2025-11-15 110848.png | F106: 1 | G106: 45975.233
A107: 130 | B107: 13 | C107: 46 | D107: Ratio & Proportion | E107: 1763370744_Screenshot 2025-11-17 144145.png | F107: 1 | G107: 45975.233
A108: 131 | B108: 13 | C108: 46 | D108: Average | E108: 1763370796_Screenshot 2025-11-17 144236.png | F108: 1 | G108: 45975.233
A109: 132 | B109: 13 | C109: 46 | D109: Mixtures & Alligation | F109: 1 | G109: 45975.234
A110: 133 | B110: 13 | C110: 46 | D110: Time,Speed and Distance | F110: 1 | G110: 45975.235
A111: 134 | B111: 13 | C111: 46 | D111: Time & Work | F111: 1 | G111: 45975.236
A112: 135 | B112: 13 | C112: 46 | D112: Pipes & Cisterns | F112: 1 | G112: 45975.236
A113: 136 | B113: 13 | C113: 46 | D113: Partnership | E113: 1763799681_red-powder-isolated-white-background.png | F113: 1 | G113: 45975.236
A114: 137 | B114: 13 | C114: 46 | D114: Boats & Streams | E114: 1764064312_Screenshot 2025-11-25 152116.png | F114: 1 | G114: 45975.237
A115: 138 | B115: 13 | C115: 45 | D115: Linear & Quadratic Equations | E115: 1764048928_Screenshot 2025-11-25 110448.png | F115: 1 | G115: 45975.237
A116: 139 | B116: 13 | C116: 45 | D116: Inequalities | E116: 1764048976_Screenshot 2025-11-25 110520.png | F116: 1 | G116: 45975.238
A117: 140 | B117: 13 | C117: 45 | D117: Functions & Graphs | F117: 1 | G117: 45975.238
A118: 141 | B118: 13 | C118: 45 | D118: Sequences & Series | E118: 1764064732_Screenshot 2025-11-25 152814.png | F118: 1 | G118: 45975.238
A119: 142 | B119: 13 | C119: 45 | D119: Logarithms, Indices, and Surds | E119: 1764064788_Screenshot 2025-11-25 152850.png | F119: 1 | G119: 45975.239
A120: 143 | B120: 13 | C120: 47 | D120: Permutations & Combinations | E120: 1764166808_Untitled design.jpg | F120: 1 | G120: 45975.242
A121: 144 | B121: 13 | C121: 47 | D121: Probability | E121: 1764220985_Untitled design (1).jpg | F121: 1 | G121: 45975.243
A122: 145 | B122: 13 | C122: 47 | D122: Set Theory & Venn Diagrams | E122: 1764231462_Untitleddesign2.jpg | F122: 1 | G122: 45975.243
A123: 146 | B123: 15 | C123: 48 | D123: Coding-Decoding, Series, Analogies | E123: 1764309327_ChatGPT_Image_Nov_28_2025_11_20_16_AM (1).jpeg | F123: 1 | G123: 45975.252
A124: 147 | B124: 15 | C124: 48 | D124: Blood Relations | E124: 1764309869_Untitleddesign3.jpg | F124: 1 | G124: 45975.252
A125: 148 | B125: 15 | C125: 48 | D125: Direction Sense | E125: 1764488795_ChatGPT_Image_Nov_30_2025_01_11_22_PM (1).jpeg | F125: 1 | G125: 45975.254
A126: 149 | B126: 15 | C126: 48 | D126: Syllogisms, Logical Deductions | E126: 1764658251_Untitleddesign1.jpg | F126: 1 | G126: 45975.254
A127: 150 | B127: 15 | C127: 48 | D127: Seating Arrangements | E127: 1764661523_Untitleddesign2.jpg | F127: 1 | G127: 45975.255
A128: 151 | B128: 15 | C128: 48 | D128: Puzzles & Input-Output | F128: 1 | G128: 45975.256
A129: 152 | B129: 15 | C129: 48 | D129: Ranking and Ordering Problems | E129: 1764737274_Untitleddesign.jpg | F129: 1 | G129: 45975.256
...
